<p>
  由于执行的异步性质，由 promise 抛出的异常（包括 <code>reject</code>）不会被嵌套的 <code>try</code> 块捕获。
  相反，使用 <code>Promise</code> 的 <code>catch</code> 方法或将其包装在 <code>await</code> 表达式中。
</p>
<h2>不合规示例</h2>
<pre>
function runPromise() {
  return Promise.reject("rejection reason");
}

function foo() {
  try { // 不合规，promise 中的代码不会执行 'try' 的 catch 子句
    runPromise();
  } catch (e) {
    console.log("Failed to run promise", e);
  }
}
</pre>
<h2>合规示例</h2>
<pre>
function foo() {
  runPromise().catch(e =&gt; console.log("Failed to run promise", e));
}

// 或
async function foo() {
  try {
    await runPromise();
  } catch (e) {
    console.log("Failed to run promise", e);
  }
}
</pre>

